<?xml version="1.0" ?>
<!-- =================================================================================== -->
<!-- |    This document was autogenerated by xacro from abb_irb120.xacro               | -->
<!-- |    EDITING THIS FILE BY HAND IS NOT RECOMMENDED                                 | -->
<!-- =================================================================================== -->
<robot name="abb_irb120" xmlns:xacro="http://ros.org/wiki/xacro">
  <!-- ///////////////// this file is improved upon the old file irb120.xacro -CW 6/6/18 ///////////////////////// -->
  <!-- Conversion were obtained from http://www.e-paint.co.uk/Lab_values.asp
       unless otherwise stated. -->
  <material name="abb_orange">
    <color rgba="0.7372549 0.3490196 0.1607843 1"/>
  </material>
  <material name="abb_graphite_white">
    <color rgba="0.7725490 0.7803922 0.7686275 1"/>
  </material>
  <material name="abb_white">
    <color rgba="0.9254902 0.9254902 0.9058824 1"/>
  </material>
  <material name="abb_pebble_gray">
    <color rgba="0.7058823 0.6901961 0.6313725 1"/>
  </material>
  <material name="abb_dark_gray">
    <color rgba="0.3450980 0.3647059 0.3686275 1"/>
  </material>
  <material name="abb_black">
    <color rgba="0.1882353 0.1960784 0.2039216 1"/>
  </material>
  <material name="abb_signal_red">
    <color rgba="0.5960784 0.1372549 0.1372549 1"/>
  </material>
  <material name="abb_carmine_red">
    <color rgba="0.5960784 0.1333333 0.1333333 1"/>
  </material>
  <material name="abb_ultramarine_blue">
    <color rgba="0.1176471 0.2117647 0.4823529 1"/>
  </material>
  <material name="abb_sky_blue">
    <color rgba="0.0431373 0.4823529 0.6901961 1"/>
  </material>
  <material name="abb_leaf_green">
    <color rgba="0.1764706 0.3529412 0.1529412 1"/>
  </material>
  <material name="abb_gray_white">
    <color rgba="0.8392157 0.8352941 0.7921569 1"/>
  </material>
  <material name="abb_pure_white">
    <color rgba="0.9411765 0.9294118 0.8823529 1"/>
  </material>
  <material name="abb_yellow">
    <color rgba="1 1 0 1"/>
  </material>
  <!-- ///////////////////////////////////////////////////////////////////////////////////////////////////////////////////// -->
  <!-- world link -->
  <link name="world"/>
  <!-- loading table model and workobject -->
  <joint name="table_joint" type="fixed">
    <parent link="world"/>
    <child link="Table"/>
    <origin rpy="0 0 0" xyz="0.2 0 0"/>
  </joint>
  <link name="Table">
    <inertial>
      <origin rpy="0 0 0" xyz="0 0 -0.06"/>
      <mass value="26.973"/>
      <inertia ixx="1" ixy="1" ixz="1" iyy="1" iyz="1" izz="1"/>
    </inertial>
    <visual>
      <origin rpy="0 0 0" xyz="0 0 -0.06"/>
      <geometry>
        <mesh filename="package://irb120_description/meshes/visual/Table.STL"/>
      </geometry>
      <material name="abb_dark_gray"/>
    </visual>
    <collision>
      <origin rpy="0 0 0" xyz="0 0 -0.06"/>
      <geometry>
        <mesh filename="package://irb120_description/meshes/collision/Table.STL"/>
      </geometry>
    </collision>
  </link>
  <!-- <joint name="workobject_joint" type="fixed">
  <parent link="Table"/>
  <child link="workobject"/>
  <origin rpy="0 0 0" xyz="0.25 0 0.01"/>
  </joint>
  <link name="workobject">
    <inertial>
      <origin xyz="0 0 0" rpy="0 0 0"/>
      <mass value="0.05"/>
      <inertia ixx="0" ixy="0" ixz="0" iyy="0" iyz="0" izz="0"/>
    </inertial>
    <visual>
      <origin xyz="0 0 0" rpy="0 0 0"/>
      <geometry>
        <mesh filename="package://irb120_description/meshes/visual/tissue_base.stl"/>
      </geometry>
      <material name="abb_carmine_red"/>
    </visual>
    <collision>
      <origin xyz="0 0 0" rpy="0 0 0"/>
      <geometry>
        <mesh filename="package://irb120_description/meshes/collision/tissue_base_simple.stl"/>
      </geometry>
    </collision>
  </link> -->
  <!-- Used for fixing robot to Gazebo 'base_link' -->
  <joint name="base_joint" type="fixed">
    <parent link="world"/>
    <child link="base_link"/>
    <origin rpy="0 0 -1.57079632679" xyz="0 0 0"/>
  </joint>
  <!-- Description of base_link -->
  <link name="base_link">
    <inertial>
      <mass value="6.215"/>
      <origin rpy="0 0 0" xyz="0 0 0"/>
      <inertia ixx="0.0247272" ixy="-8.0784E-05" ixz="0.00130902" iyy="0.0491285" iyz="-8.0419E-06" izz="0.0472376"/>
    </inertial>
    <visual>
      <origin rpy="0 0 0" xyz="0 0 0"/>
      <geometry>
        <mesh filename="package://irb120_description/meshes/visual/base_link.stl"/>
      </geometry>
      <material name="abb_orange"/>
    </visual>
    <collision>
      <origin rpy="0 0 0" xyz="0 0 0"/>
      <geometry>
        <mesh filename="package://irb120_description/meshes/collision/base_link.stl"/>
      </geometry>
    </collision>
  </link>
  <!-- ///////////////////////////////////////////////////////////////////////////////////////////////////////////////////// -->
  <!-- Joint - 1 -->
  <joint name="joint_1" type="revolute">
    <origin rpy="0 0 0" xyz="0 0 0.187"/>
    <parent link="base_link"/>
    <child link="link_1"/>
    <limit effort="100" lower="-2.87979" upper="2.87979" velocity="4.36332"/>
    <axis xyz="0 0 1"/>
    <dynamics damping="1" friction="0"/>
  </joint>
  <!-- Description of link - 1 -->
  <link name="link_1">
    <inertial>
      <mass value="3.067"/>
      <origin rpy="0 0 0" xyz="0 0 0.23841"/>
      <inertia ixx="0.0142175" ixy="-1.28579E-05" ixz="-2.31364E-05" iyy="0.0144041" iyz="1.93404E-05" izz="0.0104533"/>
    </inertial>
    <visual>
      <origin rpy="0 0 0" xyz="0 0 -0.187"/>
      <geometry>
        <mesh filename="package://irb120_description/meshes/visual/link_1.stl"/>
      </geometry>
      <material name="abb_orange"/>
    </visual>
    <collision>
      <origin rpy="0 0 0" xyz="0 0 -0.187"/>
      <geometry>
        <mesh filename="package://irb120_description/meshes/collision/link_1.stl"/>
      </geometry>
    </collision>
  </link>
  <!-- ///////////////////////////////////////////////////////////////////////////////////////////////////////////////////// -->
  <!-- Joint - 2 -->
  <joint name="joint_2" type="revolute">
    <origin rpy="-1.57079632679 0 0" xyz="0 0 0.103"/>
    <parent link="link_1"/>
    <child link="link_2"/>
    <limit effort="100" lower="-1.91986" upper="1.91986" velocity="4.36332"/>
    <axis xyz="0 0 1"/>
    <dynamics damping="1" friction="0"/>
  </joint>
  <!-- Description of link - 2 -->
  <link name="link_2">
    <inertial>
      <mass value="3.909"/>
      <origin rpy="0 0 0" xyz="0.00078 -0.00212 0.10124"/>
      <inertia ixx="0.0603111" ixy="9.83431E-06" ixz="5.72407E-05" iyy="0.041569" iyz="-0.00050497" izz="0.0259548"/>
    </inertial>
    <visual>
      <origin rpy="1.57079632679 0 0" xyz="0 0 0"/>
      <geometry>
        <mesh filename="package://irb120_description/meshes/visual/link_2.stl"/>
      </geometry>
      <material name="abb_orange"/>
    </visual>
    <collision>
      <origin rpy="1.57079632679 0 0" xyz="0 0 0"/>
      <geometry>
        <mesh filename="package://irb120_description/meshes/collision/link_2.stl"/>
      </geometry>
    </collision>
  </link>
  <!-- ///////////////////////////////////////////////////////////////////////////////////////////////////////////////////// -->
  <!-- Joint - 3 -->
  <joint name="joint_3" type="revolute">
    <origin rpy="0 0 0" xyz="0 -0.27 0"/>
    <parent link="link_2"/>
    <child link="link_3"/>
    <limit effort="100" lower="-1.91986" upper="1.22173" velocity="4.36332"/>
    <axis xyz="0 0 1"/>
    <dynamics damping="1" friction="0.0"/>
  </joint>
  <!-- Description of link - 3 -->
  <link name="link_3">
    <inertial>
      <mass value="2.944"/>
      <origin rpy="0 0 0" xyz="0.02281 0.00106 0.05791"/>
      <inertia ixx="0.00835606" ixy="-8.01545E-05" ixz="0.00142884" iyy="0.016713" iyz="-0.000182227" izz="0.0126984"/>
    </inertial>
    <visual>
      <origin rpy="1.57079632679 0 0" xyz="0 0 0"/>
      <geometry>
        <mesh filename="package://irb120_description/meshes/visual/link_3.stl"/>
      </geometry>
      <material name="abb_orange"/>
    </visual>
    <collision>
      <origin rpy="1.57079632679 0 0" xyz="0 0 0"/>
      <geometry>
        <mesh filename="package://irb120_description/meshes/collision/link_3.stl"/>
      </geometry>
    </collision>
  </link>
  <!-- ///////////////////////////////////////////////////////////////////////////////////////////////////////////////////// -->
  <!-- Joint - 4 -->
  <joint name="joint_4" type="revolute">
    <origin rpy="0 1.57079632679 0" xyz="0 -0.07 0"/>
    <parent link="link_3"/>
    <child link="link_4"/>
    <limit effort="20" lower="-2.79253" upper="2.79253" velocity="5.58505"/>
    <axis xyz="0 0 1"/>
    <dynamics damping="1" friction="0"/>
  </joint>
  <!--  Description of link - 4 -->
  <link name="link_4">
    <inertial>
      <mass value="0.1328"/>
      <origin rpy="0 0 0" xyz="0.2247 0.00015 0.00041"/>
      <inertia ixx="0.00284661" ixy="-2.12765E-05" ixz="-1.6435E-05" iyy="0.00401346" iyz="1.31336E-05" izz="0.0052535"/>
    </inertial>
    <visual>
      <origin rpy="1.57079632679 -1.57079632679 0" xyz="0 0 0"/>
      <geometry>
        <mesh filename="package://irb120_description/meshes/visual/link_4.stl"/>
      </geometry>
      <material name="abb_orange"/>
    </visual>
    <collision>
      <origin rpy="1.57079632679 -1.57079632679 0" xyz="0 0 0"/>
      <geometry>
        <mesh filename="package://irb120_description/meshes/collision/link_4.stl"/>
      </geometry>
    </collision>
  </link>
  <!-- ///////////////////////////////////////////////////////////////////////////////////////////////////////////////////// -->
  <!-- Joint - 5 -->
  <joint name="joint_5" type="revolute">
    <origin rpy="0 -1.57079632679 0" xyz="0 0 0.302"/>
    <parent link="link_4"/>
    <child link="link_5"/>
    <limit effort="20" lower="-2.094395" upper="2.094395" velocity="5.58505"/>
    <axis xyz="0 0 1"/>
    <dynamics damping="1" friction="0.0"/>
  </joint>
  <!-- Description of link - 5-->
  <link name="link_5">
    <inertial>
      <mass value="0.546"/>
      <origin rpy="0 0 0" xyz="-0.00109 3.68E-05 6.22E-05"/>
      <inertia ixx="0.00284661" ixy="-2.12765E-05" ixz="-1.6435E-05" iyy="0.00401346" iyz="1.31336E-05" izz="0.0052535"/>
    </inertial>
    <visual>
      <origin rpy="1.57079632679 0 0" xyz="0 0 0"/>
      <geometry>
        <mesh filename="package://irb120_description/meshes/visual/link_5.stl"/>
      </geometry>
      <material name="abb_orange"/>
    </visual>
    <collision>
      <origin rpy="1.57079632679 0 0" xyz="0 0 0"/>
      <geometry>
        <mesh filename="package://irb120_description/meshes/collision/link_5.stl"/>
      </geometry>
    </collision>
  </link>
  <!-- ///////////////////////////////////////////////////////////////////////////////////////////////////////////////////// -->
  <!-- Joint - 6 -->
  <joint name="joint_6" type="revolute">
    <origin rpy="0 1.57079632679 0" xyz="0.072 0 0"/>
    <parent link="link_5"/>
    <child link="link_6"/>
    <limit effort="20" lower="-6.98132" upper="6.98132" velocity="7.33038"/>
    <axis xyz="0 0 1"/>
    <dynamics damping="1" friction="0.0"/>
  </joint>
  <!-- Description of link - 6 -->
  <link name="link_6">
    <inertial>
      <mass value="0.137"/>
      <origin rpy="0 0 0" xyz="-0.00706 -0.00017 -1.32E-06"/>
      <inertia ixx="0.00284661" ixy="-2.12765E-05" ixz="-1.6435E-05" iyy="0.00401346" iyz="1.31336E-05" izz="0.0052535"/>
    </inertial>
    <visual>
      <origin rpy="-1.57079632679 -1.57079632679 0" xyz="0 0 0"/>
      <geometry>
        <mesh filename="package://irb120_description/meshes/visual/link_6.stl"/>
      </geometry>
      <material name="abb_orange"/>
    </visual>
    <collision>
      <origin rpy="-1.57079632679 -1.57079632679 0" xyz="0 0 0"/>
      <geometry>
        <mesh filename="package://irb120_description/meshes/collision/link_6.stl"/>
      </geometry>
    </collision>
  </link>
  <!-- ///////////////////////////////////////////////////////////////////////////////////////////////////////////////////// -->
  <!-- joint - 6 ___ end_effector -->
  <joint name="joint6-end_effector" type="fixed">
    <parent link="link_6"/>
    <child link="end_effector"/>
    <origin rpy="0 0 0" xyz="0 0 0.082"/>
  </joint>
  <!-- Description of end_effector -->
  <link name="end_effector">
    <inertial>
      <origin rpy="0 0 0" xyz="0 0 0"/>
      <mass value="0.01"/>
      <inertia ixx="1e-08" ixy="0" ixz="0" iyy="1e-08" iyz="0" izz="1e-08"/>
    </inertial>
    <visual>
      <origin rpy="0 0 0" xyz="0 0 -0.087"/>
      <geometry>
        <mesh filename="package://irb120_description/meshes/visual/simple_endeffector.stl" scale="0.001 0.001 0.001"/>
      </geometry>
      <material name="abb_white"/>
    </visual>
    <collision>
      <origin rpy="0 0 0" xyz="0 0 -0.087"/>
      <geometry>
        <mesh filename="package://irb120_description/meshes/collision/simple_endeffector.stl" scale="0.001 0.001 0.001"/>
      </geometry>
    </collision>
  </link>
  <transmission name="tran1">
    <type>transmission_interface/SimpleTransmission</type>
    <joint name="joint_1">
      <hardwareInterface>hardware_interface/PositionJointInterface</hardwareInterface>
    </joint>
    <actuator name="motor1">
      <mechanicalReduction>1</mechanicalReduction>
    </actuator>
  </transmission>
  <transmission name="tran2">
    <type>transmission_interface/SimpleTransmission</type>
    <joint name="joint_2">
      <hardwareInterface>hardware_interface/PositionJointInterface</hardwareInterface>
    </joint>
    <actuator name="motor2">
      <mechanicalReduction>1</mechanicalReduction>
    </actuator>
  </transmission>
  <transmission name="tran3">
    <type>transmission_interface/SimpleTransmission</type>
    <joint name="joint_3">
      <hardwareInterface>hardware_interface/PositionJointInterface</hardwareInterface>
    </joint>
    <actuator name="motor3">
      <mechanicalReduction>1</mechanicalReduction>
    </actuator>
  </transmission>
  <transmission name="tran4">
    <type>transmission_interface/SimpleTransmission</type>
    <joint name="joint_4">
      <hardwareInterface>hardware_interface/PositionJointInterface</hardwareInterface>
    </joint>
    <actuator name="motor4">
      <mechanicalReduction>1</mechanicalReduction>
    </actuator>
  </transmission>
  <transmission name="tran5">
    <type>transmission_interface/SimpleTransmission</type>
    <joint name="joint_5">
      <hardwareInterface>hardware_interface/PositionJointInterface</hardwareInterface>
    </joint>
    <actuator name="motor5">
      <mechanicalReduction>1</mechanicalReduction>
    </actuator>
  </transmission>
  <transmission name="tran6">
    <type>transmission_interface/SimpleTransmission</type>
    <joint name="joint_6">
      <hardwareInterface>hardware_interface/PositionJointInterface</hardwareInterface>
    </joint>
    <actuator name="motor6">
      <mechanicalReduction>1</mechanicalReduction>
    </actuator>
  </transmission>
  <!-- ros_control plugin -->
  <gazebo>
    <plugin filename="libgazebo_ros_control.so" name="gazebo_ros_control">
      <robotNamespace>/abb_irb120</robotNamespace>
      <robotSimType>gazebo_ros_control/DefaultRobotHWSim</robotSimType>
    </plugin>
  </gazebo>
  <!-- gazebo references -->
  <gazebo reference="base_link">
    <material>Gazebo/Orange</material>
    <turnGravityOff>true</turnGravityOff>
  </gazebo>
  <gazebo reference="link_1">
    <material>Gazebo/Orange</material>
    <turnGravityOff>true</turnGravityOff>
  </gazebo>
  <gazebo reference="link_2">
    <material>Gazebo/Orange</material>
    <turnGravityOff>true</turnGravityOff>
  </gazebo>
  <gazebo reference="link_3">
    <material>Gazebo/Orange</material>
    <turnGravityOff>true</turnGravityOff>
  </gazebo>
  <gazebo reference="link_4">
    <material>Gazebo/Orange</material>
    <turnGravityOff>true</turnGravityOff>
  </gazebo>
  <gazebo reference="link_5">
    <material>Gazebo/Orange</material>
    <turnGravityOff>true</turnGravityOff>
  </gazebo>
  <gazebo reference="link_6">
    <material>Gazebo/Black</material>
    <turnGravityOff>true</turnGravityOff>
  </gazebo>
</robot>
